<?xml version="1.0" encoding="UTF-8"?>
<robot generator="Robot 6.0.2 (Python 3.7.5 on win32)" generated="20240207 18:24:09.329" rpa="true" schemaversion="3">
<suite id="s1" name="Task" source="C:\Users\PC1\PycharmProjects\Appium\Task.robot">
<test id="s1-t1" name="Android App Automation" line="18">
<kw name="Open Chat21 Applicaiton">
<kw name="Open Application" library="AppiumLibrary">
<arg>http://0.0.0.0:4723/wd/hub</arg>
<arg>platformName=Android</arg>
<arg>deviceName=emulator-5554</arg>
<arg>appPackage=chat21.android.demo</arg>
<arg>appActivity=chat21.android.demo.SplashActivity</arg>
<arg>automationName=Uiautomator2</arg>
<doc>Opens a new application to given Appium server.
Capabilities of appium server, Android and iOS,
Please check https://github.com/appium/appium/blob/master/docs/en/writing-running-appium/server-args.md
| *Option*            | *Man.* | *Description*     |
| remote_url          | Yes    | Appium server url |
| alias               | no     | alias             |
| strict_ssl          | No     | allows you to send commands to an invalid certificate host like a self-signed one. |</doc>
<msg timestamp="20240207 18:24:10.071" level="WARN">Retrying (Retry(total=2, connect=None, read=None, redirect=None, status=None)) after connection broken by 'NewConnectionError('&lt;urllib3.connection.HTTPConnection object at 0x000001BD27C658C8&gt;: Failed to establish a new connection: [WinError 10049] The requested address is not valid in its context')': /wd/hub/session</msg>
<msg timestamp="20240207 18:24:10.076" level="WARN">Retrying (Retry(total=1, connect=None, read=None, redirect=None, status=None)) after connection broken by 'NewConnectionError('&lt;urllib3.connection.HTTPConnection object at 0x000001BD27C8B688&gt;: Failed to establish a new connection: [WinError 10049] The requested address is not valid in its context')': /wd/hub/session</msg>
<msg timestamp="20240207 18:24:10.079" level="WARN">Retrying (Retry(total=0, connect=None, read=None, redirect=None, status=None)) after connection broken by 'NewConnectionError('&lt;urllib3.connection.HTTPConnection object at 0x000001BD27C96048&gt;: Failed to establish a new connection: [WinError 10049] The requested address is not valid in its context')': /wd/hub/session</msg>
<kw name="Capture Page Screenshot" library="AppiumLibrary">
<doc>Takes a screenshot of the current page and embeds it into the log.</doc>
<msg timestamp="20240207 18:24:10.083" level="FAIL">No application is open</msg>
<status status="FAIL" starttime="20240207 18:24:10.082" endtime="20240207 18:24:10.283"/>
</kw>
<msg timestamp="20240207 18:24:10.289" level="WARN">Keyword 'Capture Page Screenshot' could not be run on failure: No application is open</msg>
<msg timestamp="20240207 18:24:10.290" level="FAIL">MaxRetryError: HTTPConnectionPool(host='0.0.0.0', port=4723): Max retries exceeded with url: /wd/hub/session (Caused by NewConnectionError('&lt;urllib3.connection.HTTPConnection object at 0x000001BD27C969C8&gt;: Failed to establish a new connection: [WinError 10049] The requested address is not valid in its context'))</msg>
<status status="FAIL" starttime="20240207 18:24:10.062" endtime="20240207 18:24:10.294"/>
</kw>
<kw name="Log" library="BuiltIn">
<arg>Hi</arg>
<doc>Logs the given message with the given level.</doc>
<status status="NOT RUN" starttime="20240207 18:24:10.294" endtime="20240207 18:24:10.294"/>
</kw>
<status status="FAIL" starttime="20240207 18:24:10.062" endtime="20240207 18:24:10.295"/>
</kw>
<status status="FAIL" starttime="20240207 18:24:10.061" endtime="20240207 18:24:10.296">MaxRetryError: HTTPConnectionPool(host='0.0.0.0', port=4723): Max retries exceeded with url: /wd/hub/session (Caused by NewConnectionError('&lt;urllib3.connection.HTTPConnection object at 0x000001BD27C969C8&gt;: Failed to establish a new connection: [WinError 10049] The requested address is not valid in its context'))</status>
</test>
<status status="FAIL" starttime="20240207 18:24:09.363" endtime="20240207 18:24:10.300"/>
</suite>
<statistics>
<total>
<stat pass="0" fail="1" skip="0">All Tasks</stat>
</total>
<tag>
</tag>
<suite>
<stat pass="0" fail="1" skip="0" id="s1" name="Task">Task</stat>
</suite>
</statistics>
<errors>
<msg timestamp="20240207 18:24:10.071" level="WARN">Retrying (Retry(total=2, connect=None, read=None, redirect=None, status=None)) after connection broken by 'NewConnectionError('&lt;urllib3.connection.HTTPConnection object at 0x000001BD27C658C8&gt;: Failed to establish a new connection: [WinError 10049] The requested address is not valid in its context')': /wd/hub/session</msg>
<msg timestamp="20240207 18:24:10.076" level="WARN">Retrying (Retry(total=1, connect=None, read=None, redirect=None, status=None)) after connection broken by 'NewConnectionError('&lt;urllib3.connection.HTTPConnection object at 0x000001BD27C8B688&gt;: Failed to establish a new connection: [WinError 10049] The requested address is not valid in its context')': /wd/hub/session</msg>
<msg timestamp="20240207 18:24:10.079" level="WARN">Retrying (Retry(total=0, connect=None, read=None, redirect=None, status=None)) after connection broken by 'NewConnectionError('&lt;urllib3.connection.HTTPConnection object at 0x000001BD27C96048&gt;: Failed to establish a new connection: [WinError 10049] The requested address is not valid in its context')': /wd/hub/session</msg>
<msg timestamp="20240207 18:24:10.289" level="WARN">Keyword 'Capture Page Screenshot' could not be run on failure: No application is open</msg>
</errors>
</robot>
