<?xml version="1.0" encoding="UTF-8"?>
<robot generator="Robot 6.0.2 (Python 3.7.5 on win32)" generated="20240206 15:53:45.314" rpa="true" schemaversion="3">
<suite id="s1" name="Task" source="C:\Users\PC1\PycharmProjects\Appium\Task.robot">
<test id="s1-t1" name="Android App Automation" line="11">
<kw name="Open an Applicaiton">
<kw name="Open Application" library="AppiumLibrary">
<arg>remote_url</arg>
<doc>Opens a new application to given Appium server.
Capabilities of appium server, Android and iOS,
Please check https://github.com/appium/appium/blob/master/docs/en/writing-running-appium/server-args.md
| *Option*            | *Man.* | *Description*     |
| remote_url          | Yes    | Appium server url |
| alias               | no     | alias             |
| strict_ssl          | No     | allows you to send commands to an invalid certificate host like a self-signed one. |</doc>
<msg timestamp="20240206 15:53:52.655" level="WARN">Retrying (Retry(total=2, connect=None, read=None, redirect=None, status=None)) after connection broken by 'NewConnectionError('&lt;urllib3.connection.HTTPConnection object at 0x000002113CBBA4C8&gt;: Failed to establish a new connection: [Errno 11001] getaddrinfo failed')': /session</msg>
<msg timestamp="20240206 15:53:59.540" level="WARN">Retrying (Retry(total=1, connect=None, read=None, redirect=None, status=None)) after connection broken by 'NewConnectionError('&lt;urllib3.connection.HTTPConnection object at 0x000002113CBDD3C8&gt;: Failed to establish a new connection: [Errno 11001] getaddrinfo failed')': /session</msg>
<msg timestamp="20240206 15:54:06.402" level="WARN">Retrying (Retry(total=0, connect=None, read=None, redirect=None, status=None)) after connection broken by 'NewConnectionError('&lt;urllib3.connection.HTTPConnection object at 0x000002113CBDDDC8&gt;: Failed to establish a new connection: [Errno 11001] getaddrinfo failed')': /session</msg>
<kw name="Capture Page Screenshot" library="AppiumLibrary">
<doc>Takes a screenshot of the current page and embeds it into the log.</doc>
<msg timestamp="20240206 15:54:13.238" level="FAIL">No application is open</msg>
<status status="FAIL" starttime="20240206 15:54:13.237" endtime="20240206 15:54:13.249"/>
</kw>
<msg timestamp="20240206 15:54:13.252" level="WARN">Keyword 'Capture Page Screenshot' could not be run on failure: No application is open</msg>
<msg timestamp="20240206 15:54:13.256" level="FAIL">MaxRetryError: HTTPConnectionPool(host='remote_url', port=80): Max retries exceeded with url: /session (Caused by NewConnectionError('&lt;urllib3.connection.HTTPConnection object at 0x000002113CBE6748&gt;: Failed to establish a new connection: [Errno 11001] getaddrinfo failed'))</msg>
<status status="FAIL" starttime="20240206 15:53:45.817" endtime="20240206 15:54:13.259"/>
</kw>
<status status="FAIL" starttime="20240206 15:53:45.816" endtime="20240206 15:54:13.259"/>
</kw>
<status status="FAIL" starttime="20240206 15:53:45.815" endtime="20240206 15:54:13.260">MaxRetryError: HTTPConnectionPool(host='remote_url', port=80): Max retries exceeded with url: /session (Caused by NewConnectionError('&lt;urllib3.connection.HTTPConnection object at 0x000002113CBE6748&gt;: Failed to establish a new connection: [Errno 11001] getaddrinfo failed'))</status>
</test>
<status status="FAIL" starttime="20240206 15:53:45.319" endtime="20240206 15:54:13.263"/>
</suite>
<statistics>
<total>
<stat pass="0" fail="1" skip="0">All Tasks</stat>
</total>
<tag>
</tag>
<suite>
<stat pass="0" fail="1" skip="0" id="s1" name="Task">Task</stat>
</suite>
</statistics>
<errors>
<msg timestamp="20240206 15:53:52.655" level="WARN">Retrying (Retry(total=2, connect=None, read=None, redirect=None, status=None)) after connection broken by 'NewConnectionError('&lt;urllib3.connection.HTTPConnection object at 0x000002113CBBA4C8&gt;: Failed to establish a new connection: [Errno 11001] getaddrinfo failed')': /session</msg>
<msg timestamp="20240206 15:53:59.540" level="WARN">Retrying (Retry(total=1, connect=None, read=None, redirect=None, status=None)) after connection broken by 'NewConnectionError('&lt;urllib3.connection.HTTPConnection object at 0x000002113CBDD3C8&gt;: Failed to establish a new connection: [Errno 11001] getaddrinfo failed')': /session</msg>
<msg timestamp="20240206 15:54:06.402" level="WARN">Retrying (Retry(total=0, connect=None, read=None, redirect=None, status=None)) after connection broken by 'NewConnectionError('&lt;urllib3.connection.HTTPConnection object at 0x000002113CBDDDC8&gt;: Failed to establish a new connection: [Errno 11001] getaddrinfo failed')': /session</msg>
<msg timestamp="20240206 15:54:13.252" level="WARN">Keyword 'Capture Page Screenshot' could not be run on failure: No application is open</msg>
</errors>
</robot>
